<mujoco model="single">
    <option collision="all" timestep="0.001" gravity="0 0 -9.81" cone="elliptic" />
    <compiler angle="radian" />
	<default>
		<!--joint limited="false" damping="0.1" stiffness="0" armature="0.0001" user="0"/-->
		<!--geom solref="0.008 1" solimp="0.95 0.95 0.01" margin="0.001" user="0" condim="6"/-->
		<!--geom condim="6" solimp="0.99 0.99 0.01" />
		<motor ctrllimited="false" ctrlrange="-1 1"/>
		<position ctrllimited="false"/-->

    </default>
    <visual>
        <headlight ambient="0.4 0.4 0.4" diffuse="0.4 0.4 0.4" specular="0.0 0.0 0.0" active="1"/>
    </visual>
    <asset>
        <texture builtin="checker" height="512" name="texplane" rgb1=".2 .3 .4" rgb2=".1 .15 .2" type="2d" width="512" />
        <material name="MatPlane" reflectance="0.5" shininess="0.01" specular="0.1" texrepeat="1 1" texture="texplane" texuniform="true" />
        <material name="black" rgba="0.0 0.0 0.0 1.0"/>
        <material name="blue" rgba="0.0 0.0 0.8 1.0"/>
        <material name="green" rgba="0.0 0.8 0.0 1.0"/>
        <material name="grey" rgba="0.2 0.2 0.2 1.0"/>
        <material name="orange" rgba="1.0 0.423529411765 0.0392156862745 1.0"/>
        <material name="brown" rgba="0.870588235294 0.811764705882 0.764705882353 1.0"/>
        <material name="red" rgba="0.8 0.0 0.0 1.0"/>
        <material name="white" rgba="1.0 1.0 1.0 1.0"/>
    </asset>
    <worldbody>
        <geom name="ground_plane" type="plane" size="5 5 0.1" material="MatPlane" rgba="1 1 1 1"/>
        <body name="link1">
            <geom name="link1_geom" pos="0 0 1.0" type="box" size="0.05 0.05 1" material="orange"/>
            <inertial pos="0 0 1.0" mass="1" diaginertia="1.0 1.0 1.0"/>
            <body name="link2" pos="0 0.1 1.95">
                <joint name="joint1" pos="0 0 0" axis="0 1 0" damping="0.7" />
                <geom name="link2_geom" pos="0 0 0.45" type="box" size="0.05 0.05 0.5" material="blue"/>
                <inertial pos="0 0 0.45" mass="1" diaginertia="1.0 1.0 1.0"/>
                <body name="link3" pos="0 0.1 0.9">
                    <joint name="joint2" pos="0 0 0" axis="0 1 0" damping="0.7" />
                    <geom name="link3_geom" pos="0 0 0.45" type="box" size="0.05 0.05 0.5" material="orange"/>
                    <inertial pos="0 0 0.45" mass="1" diaginertia="1.0 1.0 1.0"/>
                </body>
            </body>
        </body>
    </worldbody>
    <contact>
        <exclude body1="link1" body2="link2" />
        <exclude body1="link2" body2="link3" />
        <exclude body1="link1" body2="link3" />
    </contact>
</mujoco>
